const Condominio = require('../models/Condominio')

class condominioController {
    constructor(name){
        this.name = name
    }
    async create(req,res){   
         async function inserirUsuario(){
            try{
                let dataUser =  await {
                    nome:req.body.nome,
                    telefone:req.body.telefone,
                    endereco:req.body.endereco,
                    cidade:req.body.cidade,
                    estado:req.body.estado,
                    cep:req.body.cep,
                }
                let resultInsert = await Condominio.insertUser(dataUser)
                res.json(resultInsert.result)
            }catch(err){
                console.log(err)
                let catchErro = {erro:`Houve uma falha no servidor ao cadastrar um novo ${this.name}`}
                res.status(500).json(catchErro)
            }
         }       
         inserirUsuario() 
    };

    async showAll(req,res){
        try{
            let resultFindAll = await Condominio.findAll()
            res.json(resultFindAll.result)
        }catch(err){
            console.log(err)
            let catchErro = {erro:`Houve uma falha no servidor ao listar todos ${this.name}s`}
            res.status(500).json(catchErro)
        }     
    };

    async showById(req,res){    
        try{
            let resultFindId = await Condominio.findById(req.params.id)
            res.json(resultFindId.result)
        }catch(err){
            console.log(err)
            let catchErro = {erro:`Houve uma falha no servidor ao listar ${this.name} pelo id`}
            res.status(500).json(catchErro)
        }
    };

    async showByCidade(req,res){    
        try{
            let resultFindNumero = await Condominio.findAllByCidade(req.params.cidade)
            res.json(resultFindNumero.result)
        }catch(err){
            console.log(err)
            let catchErro = {erro:`Houve uma falha no servidor ao listar ${this.name} pela cidade`}
            res.status(500).json(catchErro)
        }
    };

    async editById(req,res){
        try{
            let dataUpdate = await {
                id:req.body.id,
                nome:req.body.nome,
                telefone:req.body.telefone,
                endereco:req.body.endereco,
                cidade:req.body.cidade,
                estado:req.body.estado,
                cpf:req.body.cpf,
            }
            let resultUpdate = await Condominio.updateById(dataUpdate)
            res.json(resultUpdate.result)
        }catch(err){
            console.log(err)
            let catchErro = {erro:`Houve uma falha no servidor ao editar ${this.name} pelo id`}
            res.status(500).json(catchErro)
        }
    };

    async removeById(req,res){
        try{
           let resultDelete = await Condominio.deleteById(req.params.id)
           res.json(resultDelete.result)
        }catch(err){
            console.log(err)
            let catchErro = {erro:`Houve uma falha no servidor ao remover ${this.name} pelo id`}
            res.status(500).json(catchErro)
        }
    }
}

module.exports = new condominioController ('condominio')