const Noticia = require('../models/Noticia')

class noticiaController {
    constructor(name){
        this.name = name
    }
    async create(req,res){   
         async function inserirUsuario(){
            try{
                let dataUser =  await {
                    data:new Date().toLocaleDateString(),
                    titulo:req.body.titulo,
                    conteudo:req.body.conteudo,
                }
                let resultInsert = await Noticia.insertUser(dataUser)
                res.json(resultInsert.result)
            }catch(err){
                console.log(err)
                let catchErro = {erro:`Houve uma falha no servidor ao cadastrar uma nova ${this.name}`}
                res.json(catchErro)
            }
         }       
         inserirUsuario() 
    };

    async showAll(req,res){
        try{
            let resultFindAll = await Noticia.findAll()
            res.json(resultFindAll.result)
        }catch(err){
            console.log(err)
            let catchErro = {erro:`Houve uma falha no servidor ao listar todas as ${this.name}s`}
            res.json(catchErro)
        }     
    };

    async showById(req,res){    
        try{
            let resultFindId = await Noticia.findById(req.params.id)
            res.json(resultFindId.result)
        }catch(err){
            console.log(err)
            let catchErro = {erro:`Houve uma falha no servidor ao listar ${this.name} pelo id`}
            res.json(catchErro)
        }
    };

    async showBydata(req,res){    
        try{
            let resultFindData = await Noticia.findAllByData(req.params.data)
            res.json(resultFindData.result)
        }catch(err){
            console.log(err)
            let catchErro = {erro:`Houve uma falha no servidor ao listar ${this.name} pela data`}
            res.json(catchErro)
        }
    };

    async editById(req,res){
        try{
            let dataUpdate = await {
                id:req.body.id,
                data:req.body.data,
                titulo:req.body.titulo,
                conteudo:req.body.conteudo,
            }
            let resultUpdate = await Noticia.updateById(dataUpdate)
            res.json(resultUpdate.result)
        }catch(err){
            console.log(err)
            let catchErro = {erro:`Houve uma falha no servidor ao editar ${this.name} pelo id`}
            res.json(catchErro)
        }
    };

    async removeById(req,res){
        try{
           let resultDelete = await Noticia.deleteById(req.params.id)
           res.json(resultDelete.result)
        }catch(err){
            console.log(err)
            let catchErro = {erro:`Houve uma falha no servidor ao remover ${this.name} pelo id`}
            res.json(catchErro)
        }
    }
}

module.exports = new noticiaController ('noticia')